# [异常](https://blog.csdn.net/qq_29229567/article/details/80773970)

## java3种处理系统错误的机制

> `抛出一个异常`
>
> `日志`
>
> `使用断言`

## [Java finally语句到底是在return之前还是之后执行？](https://www.cnblogs.com/lanxuezaipiao/p/3440471.html)

> 在执行 return 之后的语句之后，在 return 之前

```java
public static void main(String[] args) {
    System.out.println(getNum()); // 50
}
public static int getNum() {

    int num = 30;
    try {
        return num += 20;
    } finally {
        System.out.println(num); // 50
    }
}
```

**`Throwable`**： 有两个重要的子类：Exception（异常）和 Error（错误），二者都是 Java 异常处理的重要子类，各自都包含大量子类。异常和错误的区别是：异常能被程序本身可以处理，错误是无法处理。

![](java_ack_imgs\Exception_Summary.png)

`Error`（错误）:是程序无法处理的错误，表示运行应用程序中较严重问题。大多数错误与代码编写者执行的操作无关，而表示代码运行时 JVM（Java 虚拟机）出现的问题。例如，Java虚拟机运行错误（Virtual MachineError），当 JVM 不再有继续执行操作所需的内存资源时，将出现 OutOfMemoryError。这些异常发生时，Java虚拟机（JVM）一般会选择线程终止。这些错误表示故障发生于虚拟机自身、或者发生在虚拟机试图执行应用时，如Java虚拟机运行错误（Virtual MachineError）、类定义错误（NoClassDefFoundError）等。这些错误是不可查的，因为它们在应用程序的控制和处理能力之 外，而且绝大多数是程序运行时不允许出现的状况。对于设计合理的应用程序来说，即使确实发生了错误，本质上也不应该试图去处理它所引起的异常状况。在 Java中，错误通过Error的子类描述。 

`Exception`（异常）分两大类：运行时异常和非运行时异常(编译异常)。程序中应当尽可能去处理这些异常。
      1.运行时异常：都是RuntimeException类及其子类异常，如NullPointerException(空指针异常)、IndexOutOfBoundsException(下标越界异常)等，这些异常是非受查异常，程序中可以选择捕获处理，也可以不处理。这些异常一般是由程序逻辑错误引起的，程序应该从逻辑角度尽可能避免这类异常的发生。**运行时异常的特点是Java编译器不会检查它，也就是说，当程序中可能出现这类异常，即使没有用try-catch语句捕获它，也没有用throws子句声明抛出它，也会编译通过。**
      2.非运行时异常 （编译异常）：是 RuntimeException 以外的异常，**类型上都属于Exception类及其子类**。从程序语法角度讲是必须进行处理的异常，如果不处理，程序就不能编译通过。如IOException、SQLException 等以及用户自定义的Exception异常，**一般情况下不自定义检查异常。**

## 受查异常和非受查异常

派生于 Error 和 RuntimeException 类的所有异常被称为非受查异常，所有其他的异常被称为受查异常。

## 抛出异常

1. 调用的方法抛出受查异常的方法
2. 程序在运行过程中发生错误，并且利用 throw 语句抛出一个受查异常（这个是java方法体中抛出异常后的方式 ），同样可以利用 throws 在方法层次抛出异常
   ```java
   private int childMethod() throws ParentException { // throws 
      throw new ChildException(); // throw 
   }
   ```

## 抛出异常的规范

1. 派生于RunTimeException类的异常不应该被抛出，而是应该就地解决，尽可能避免这种错误。

2. 派生于 Error 类的异常也不应该被抛出，因为我们对其没有任何处理能力，只能尽可能避免

3. 只有受查异常，我们要么就地解决，要么抛出异常，使得调用该方法的程序员异常错误，==但有一点，如果当前方法是覆盖父类的方法，如果父类方法没有抛出受查异常，子类也不能抛出异常，只能就地解决==

4. 如果在子类中覆写父类方法，子类方法在生命中声明的`受查异常`不能比父类方法中声明的异常更通用（也就是说，子类方法方法声明的异常只能是父类异常的子类（可以有多个子类））`受查异常，受查异常`   ==并且，子类要么抛出父类声明异常的相同异常或者子类，要么不抛出异常==

   ```java
   class OverWeight {
       public void printInfo2() throws IOException{
           System.out.println("OverWeight 类的异常");
       }
   }
   class OverChild extends OverWeight {
       @Override
       public void printInfo2() throws EOFException, FileNotFoundException  {}
   }
   ```

5. 如果父类没有声明受查异常，子类也不能声明受查异常

6. 记住，Exception 也是受查异常 IOException 的父类，所以也是受查异常

7. 如果，调用的方法抛出了受查异常，就必须对其处理，要么继续传递

8. 如果，实现的两个接口都抛出了受查异常，并且受查异常是同一层次的，这个时候就会有冲突（同样，父类和接口抛出了同一层次不同的受查异常也是会冲突的）

   ```java
   public interface Sing {
       void printInfo() throws FileNotFoundException;
   }
   interface Sing2 {
       void printInfo() throws EOFException;
   }
   class Sing3 {
       public void printInfo() throws EOFException {
       }
   }
   // error
   class Sing4 implements Sing, Sing2 {
       @Override
       public void printInfo() throws EOFException {
       }
   }
   // error
   class Sing5 extends Sing3 implements Sing {
   }
   ```

9. 接第8条，如果，实现的两个接口都抛出了受查异常，并且`受查异常是一个是父类，另一个是子类`，这个时候就会有冲突（同样，父类和接口抛出`是一个是父类，另一个是子类`的受查异常==并不会出现冲突==    有两种方法，`1. 要么抛出子类异常（只能是被声明的子类异常或者是子类异常的派生类）`    ==  `2. 要么不抛出异常`

   ```java
   public interface Sing {
       void printInfo() throws IOException;
   }
   interface Sing2 {
       void printInfo() throws EOFException;
   }
   class Sing4 implements Sing, Sing2 {
       @Override
       public void printInfo() {
       }
   /*    @Override
       public void printInfo() throws EOFException {
       }*/
   }
   ```

10. `第4条规则也只限于受查异常，而非查异常则不满足这种限制`

   ```java
   // 父类声明 受查异常，子类也可以不声明， 非受查异常 无所谓
   class OverWeight {
       public void printInfo2() throws IOException{
           System.out.println("OverWeight 类的异常");
       }
   }
   class OverChild extends OverWeight {
       @Override
       public void printInfo2() throws ArithmeticException {}
   }
   ```

   ```java
   // 覆写方法声明不一样的非受查异常
   class OverWeight {
       public void printInfo2() throws NullPointerException{}
   }
   class OverChild extends OverWeight {
       @Override
       public void printInfo2() throws ArithmeticException {}
   }
   ```

   ```java
   // 父类声明 异常子类，而子类方法声明异常父类
   class OverWeight {
       public void printInfo2() throws ArithmeticException{}
   }
   class OverChild extends OverWeight {
       @Override
       public void printInfo2() throws RuntimeException {}
   }
   ```

## 捕获多个异常

> 可以捕获多个异常，
>
> 也可以在同一个catch 中捕获多个异常，但是必须两个异常不存在`子类关系`

```java
try {
    // A
}catch (ArithmeticException | NullPointerException e) {
    // B
}
```

```java
try {
    // A
}catch (ArithmeticException | NullPointerException e) {
    // B
}catch(RuntimeException e) {
    // C
}
```

## **try-catch 和 switch 的区别**

> 1. catch 是为了捕获到 异常，并对其进行处理，抛出的异常会匹配离异常最近的 catch 语句，并且，一旦匹配成功，就不会再执行后面的catch, 但是如果没有匹配的异常处理，就会终止程序
    ```java
    
	class ParentException extends Exception {
	}

	class ChildException extends ParentException {
	}
	
	public class PredicateTest {

	    public static void main(String[] args) {

		PredicateTest pt = new PredicateTest();
		try {
		    pt.childMethod(); 				// 代码 1
		} catch (ChildException e) {
		    System.out.println("child 捕获异常");		// 代码 2
		}catch(ParentException e) {
		    System.out.println("parent 捕获异常");			// 代码 3
		} catch (Exception e) {
		    System.out.println("exception 捕获异常");		// 代码 4
		} 
	    }

	    private int childMethod() throws ParentException {
		throw new ChildException();		// 代码 5
	    }

	}
    ```
> 2. 代码 1 调用 childMethod ，会抛出 ChildException 类型的异常，并会向上转型为 ParentException，但异常的实际类型是 ChildException ，因此，会被代码 2 捕获
> 3. switch 和catch 不同的是，必须添加 break, 否则，一旦匹配， 也会依次执行后面的 case 语句。

## 异常的层次

> 记住， catch 语句只匹配 同层次的try 语句的异常，如下面例子， 尽管在第一个 catch 语句中 抛出了NullPointerException的异常，但是不能被第二个catch 捕获

```java
try {
    System.out.println("抛出异常 1");
    // A
    throw new ArithmeticException("就是想抛出异常1");
} catch (ArithmeticException e) {
    System.out.println("抛出异常 2");
    // B
    RuntimeException re = new NullPointerException("就是想抛出异常2");
    re.initCause(e);
    throw re;
} catch (RuntimeException e) {
    System.out.println("抛出异常 3");
    // C
}
/*
抛出异常 1
抛出异常 2
*/
```

## 再次抛出异常与异常链

> 在catch子句中可以再次抛出异常，这样做的目的是改变异常的类型，有一种更好的处理方法，并且将原始异常设置为新异常的原因

```java
try {
    System.out.println("抛出异常 1");
    // A
    throw new ArithmeticException("就是想抛出异常1");
} catch (ArithmeticException e) {
    System.out.println("抛出异常 2");
    // B
    RuntimeException re = new NullPointerException("就是想抛出异常2");
    re.initCause(e);
} 
/*
java.lang.NullPointerException: 就是想抛出异常2
	at com.bourne.exceptions.TestException.main(TestException.java:81)
Caused by: java.lang.ArithmeticException: 就是想抛出异常1
	at com.bourne.exceptions.TestException.main(TestException.java:77)
*/
try {
    testException.printInfo6();
} catch (RuntimeException e) {
    e.printStackTrace(System.out);
    System.out.println(e.getCause());
    System.out.println(e.getMessage());
}
/*
java.lang.NullPointerException: 空
	at com.bourne.exceptions.TestException.printInfo6(TestException.java:99)
	at com.bourne.exceptions.TestException.main(TestException.java:116)
Caused by: java.lang.ArithmeticException: / by zero
	at com.bourne.exceptions.TestException.printInfo6(TestException.java:97)
	... 1 more
java.lang.ArithmeticException: / by zero
空
*/
```

## finally

> finally 语句无论是发生异常还是未发生异常，都会被执行，详情例子请参考*(java核心I p275)*
>
> 1. 如果未发生异常，则会执行try 所有语句以及finally 中所有语句，以及之后的语句
>
> 2. 如果发生异常，并可以匹配到异常，则会执行（1） try 异常之前语句，（2） catch 语句， （3） finally 语句，
>
>    如果 catch 没有抛出异常，则依旧会执行 try -catch-finally 语句之后的语句
>
>    如果 catch 抛出异常，则只会执行到finally语句，之后不再执行
>
> 3. 如果发生异常，但是未被catch 捕获，不会执行 catch, 只会执行 finally 语句， 并且会抛出异常给调用者

### 未发生异常

```java
try {
    System.out.println("1");
    System.out.println("2");
} catch (ArithmeticException e) {
    System.out.println("3");
    System.out.println("4");
}finally {
    System.out.println("5");
}
System.out.println("6");
/*
1
2
5
6
*/
```

### try 中发生异常,catch 未出现异常

```java
try {
    System.out.println("1");
    // 出错
    int i = 1 / 0;
    System.out.println("2");
} catch (ArithmeticException e) {
    System.out.println("3");
    // 出错
    System.out.println("4");
}finally {
    System.out.println("5");
}
System.out.println("6");
/*
1
3
4
5
6
*/
```

### try 发生异常，catch 发生异常

```java
try {
    System.out.println("1");
    // 出错
    int i = 1 / 0;
    System.out.println("2");
} catch (ArithmeticException e) {
    System.out.println("3");
    int i = 1 / 0;
    System.out.println("4");
}finally {
    System.out.println("5");
}
System.out.println("6");
/*
1
3
5
抛出异常， catch 中的非受查异常未捕获
*/
```

### try 发生异常， catch 未捕获

```java
try {
    System.out.println("1");
    // 出错
    int i = 1 / 0;
    System.out.println("2");
} catch (NullPointerException e) {
    System.out.println("3");
    int i = 1 / 0;
    System.out.println("4");
}finally {
    System.out.println("5");
}
System.out.println("6");
/*
1
5 
try 中异常未被捕获
*/
```

## 关闭资源

![](java_ack_imgs\try_catch_finally_resources.png)

> 如果 构造对象失败，也就是说 打开文件失败，只需要捕获异常，没有必要关闭文件

![](java_ack_imgs\try_catch_finally_resources2.png)

```java
// 直接省略了 内部的catch, 内部的捕获异常块只是为了关闭文件，而不是捕获异常， 只要是 try 中抛出的异常都会被 外部的catch 捕获
try {
    System.out.println("抛出异常 1");
    is = new FileInputStream("abc.txt");
    try {
        Integer name = null;
        while((name = is.read()) != null) {
            System.out.println(name);
        }
    }finally {
        is.close();
    }
} catch (IOException e) {
    System.out.println("抛出异常 2");
    e.printStackTrace(System.out);
}
```

> 这一个将关闭文件放置在第一个 try 块中，如果 构造对象失败， 抛出异常，执行 `5`， 因为没有打开文件，所以没有必要关闭文件， 但是如果构造成功，只是在 try 中的 `2` 出现异常，才会捕获异常，并且会执行 `3` 和 `4`（关闭文件）
>
> 有一点要注意， 如果 `3` 和 `4` 出现异常，同样会被 `5` 处理（其实 close 也是会抛出异常的）

```java
public void close() throws IOException {}
```

## try-with-resources

```java
try(FileInputStream fis = new FileInputStream("1.txt")) {

}catch (IOException e) {
    e.printStackTrace();
}
```

## 异常丢失

```java
// 1.
try{
    try{
        throw new AException();
    }finally{
        throw new BException();
    }
}catch(Exception e){
    System.out.println(e);
}
// finally 一定会执行，因此，在内部 try 块中抛出异常，但是会执行 finally 块， AException 就会被丢弃，而 catch 只能捕获 BException 
// 2. 
try{
 	throw new AException();  
}finally{
    return;
}
// AException 异常未被捕获，抛出异常，执行 finally ,return 会丢弃原先抛出的异常
```

## 怎样解决异常丢失

> 抑制的异常需要使用 getSuppress() 获取， 而 正常抛出的异常直接输出就可以

```java
try {
    FileInputStream fis = new FileInputStream("q.er");
    Throwable th = null;
    try {
        fis.read(); // 读取信息 如果，出现异常，被捕获
    } catch (IOException e) {// 捕获 内部 try 中的错误，利用 th 记录 异常对象的地址
        th = e;
        throw th; // 一定要抛出异常
    } finally {     // 进行关闭操作
        if (fis != null) {
            if (th != null) {   // 如果 th 不为空，说明 try 块中抛出异常，这里如果再抛出异常，
                try {           // 则进行异常抑制，当然抑制的是后发生的异常
                    fis.close();
                } catch (IOException e) {
                    th.addSuppressed(e);
                }
            } else {    // 如果，th 为空，则直接进行关闭
                fis.close();
            }
        }
    }
} catch (IOException e) {   // 这里接受 try 块中的所有异常
    System.out.println(e);   // java.lang.ArithmeticException: / by zero
    System.out.println(e.getSuppressed()[0]); // java.lang.NullPointerException
}
```

# 断言

> 断言允许在代码测试期间在代码中插入一些检查语句，当代码发布时会被自动的移走
>
> 什么时候使用断言（断言的特点）
>
> 1. 断言失败是致命的，不可恢复的，不应该使用断言项程序的其他部分通告发生了可恢复性的错误，或者，不应该作为程序向用户通告问题的手段
> 2. 断言之应该用于测试阶段确定程序内部的错误位置
> 3. 断言检查只用于开发和测试阶段，

## 断言的使用

> javac 编译单元
>
> java -enableassertions 二进制文件

```java
/*
表示 num 必须是正整数，如果不满足条件，则出现不可恢复的异常
*/
public static double getSqrt(int num) {
    assert num > 0 : "num < 0";
    return sqrt(num);
}
```
